Workbook

Sheet Clientes
A1: CodCliente | B1: NomeCliente | C1: CodRamoAtiv | D1: DescRamoAtiv | E1: CodFinalidVenda | F1: DescFinalidVenda | G1: Varejo | H1: Atacado | I1: Industria | J1: Servi‡o
A2: 1 | B2: IMA TECIDOS DA MODA LTDA | C2: 20 | D2: =LOOKUP(C2,RamoAtividade!A:A,RamoAtividade!B:B) -> OUTROS SEGMENTOS | E2: 1 | F2: =LOOKUP(E2,Finalidades!A:A,Finalidades!B:B) -> Envio para Deposito | G2: S | H2: N | I2: N | J2: N
A3: 17 | B3: VIACAO PASSARO VERDE LTDA | C3: 20 | D3: =LOOKUP(C3,RamoAtividade!A:A,RamoAtividade!B:B) -> OUTROS SEGMENTOS | E3: 0 | F3: =LOOKUP(E3,Finalidades!A:A,Finalidades!B:B) -> #N/A | G3: N | H3: N | I3: N | J3: N
A4: 58 | B4: IND COM CONF ITIMITHUS LTDA ME | C4: 8 | D4: =LOOKUP(C4,RamoAtividade!A:A,RamoAtividade!B:B) -> FACCIONISTA | E4: 0 | F4: =LOOKUP(E4,Finalidades!A:A,Finalidades!B:B) -> #N/A | G4: N | H4: N | I4: N | J4: N
A5: 72 | B5: KRINDGES INDUSTRIAL LTDA | C5: 20 | D5: =LOOKUP(C5,RamoAtividade!A:A,RamoAtividade!B:B) -> OUTROS SEGMENTOS | E5: 0 | F5: =LOOKUP(E5,Finalidades!A:A,Finalidades!B:B) -> #N/A | G5: N | H5: N | I5: N | J5: N
A6: 75 | B6: PEDRINHO TEC CONF LTDA | C6: 12 | D6: =LOOKUP(C6,RamoAtividade!A:A,RamoAtividade!B:B) -> MODA FESTA | E6: 0 | F6: =LOOKUP(E6,Finalidades!A:A,Finalidades!B:B) -> #N/A | G6: N | H6: N | I6: N | J6: N
A7: 81 | B7: TEC JOTALIRA LTDA | C7: 3 | D7: =LOOKUP(C7,RamoAtividade!A:A,RamoAtividade!B:B) -> CAMA, MESA,BANHO E ENXOVAL | E7: 0 | F7: =LOOKUP(E7,Finalidades!A:A,Finalidades!B:B) -> #N/A | G7: N | H7: N | I7: N | J7: N
A8: 84 | B8: WILLER APARECIDO CRUZ | C8: 0 | D8: =LOOKUP(C8,RamoAtividade!A:A,RamoAtividade!B:B) -> #N/A | E8: 0 | F8: =LOOKUP(E8,Finalidades!A:A,Finalidades!B:B) -> #N/A | G8: N | H8: N | I8: N | J8: N
A9: 95 | B9: CODE BLUE CONF E CALCADOS LTDA ME | C9: 17 | D9: =LOOKUP(C9,RamoAtividade!A:A,RamoAtividade!B:B) -> TECELAGEM | E9: 0 | F9: =LOOKUP(E9,Finalidades!A:A,Finalidades!B:B) -> #N/A | G9: N | H9: N | I9: N | J9: N
A10: 103 | B10: MARIA MARGARIDA V MONTEIRO ME | C10: 9 | D10: =LOOKUP(C10,RamoAtividade!A:A,RamoAtividade!B:B) -> FEIRANTE | E10: 0 | F10: =LOOKUP(E10,Finalidades!A:A,Finalidades!B:B) -> #N/A | G10: N | H10: N | I10: N | J10: N
A11: 113 | B11: CONF LASALA LTDA EPP | C11: 12 | D11: =LOOKUP(C11,RamoAtividade!A:A,RamoAtividade!B:B) -> MODA FESTA | E11: 0 | F11: =LOOKUP(E11,Finalidades!A:A,Finalidades!B:B) -> #N/A | G11: N | H11: N | I11: N | J11: N
A12: 118 | B12: ESPA€O TEXTIL LTDA | C12: 3 | D12: =LOOKUP(C12,RamoAtividade!A:A,RamoAtividade!B:B) -> CAMA, MESA,BANHO E ENXOVAL | E12: 0 | F12: =LOOKUP(E12,Finalidades!A:A,Finalidades!B:B) -> #N/A | G12: N | H12: N | I12: N | J12: N
A13: 119 | B13: COML TEC CONF ALMEIDA BRAGA LTDA | C13: 9 | D13: =LOOKUP(C13,RamoAtividade!A:A,RamoAtividade!B:B) -> FEIRANTE | E13: 0 | F13: =LOOKUP(E13,Finalidades!A:A,Finalidades!B:B) -> #N/A | G13: N | H13: N | I13: N | J13: N
... A2529: 25505 | B2529: MODA SHAPER LTDA ME | C2529: 20 | D2529: =LOOKUP(C2529,RamoAtividade!A:A,RamoAtividade!B:B) -> OUTROS SEGMENTOS | E2529: 0 | F2529: =LOOKUP(E2529,Finalidades!A:A,Finalidades!B:B) -> #N/A | G2529: N | H2529: N | I2529: N | J2529: N
A2530: 25506 | B2530: B27 JEANS CONF LTDA ME | C2530: 0 | D2530: =LOOKUP(C2530,RamoAtividade!A:A,RamoAtividade!B:B) -> #N/A | E2530: 0 | F2530: =LOOKUP(E2530,Finalidades!A:A,Finalidades!B:B) -> #N/A
A2531: 25509 | B2531: SERELEPE CONF LTDA EPP | C2531: 12 | D2531: =LOOKUP(C2531,RamoAtividade!A:A,RamoAtividade!B:B) -> MODA FESTA | E2531: 0 | F2531: =LOOKUP(E2531,Finalidades!A:A,Finalidades!B:B) -> #N/A | G2531: N | H2531: N | I2531: N | J2531: N
A2532: 25516 | B2532: ROSA MORENA CONF LTDA - ME | C2532: 0 | D2532: =LOOKUP(C2532,RamoAtividade!A:A,RamoAtividade!B:B) -> #N/A | E2532: 0 | F2532: =LOOKUP(E2532,Finalidades!A:A,Finalidades!B:B) -> #N/A
A2533: 25517 | B2533: JAC INDL DE MODAS LTDA | C2533: 12 | D2533: =LOOKUP(C2533,RamoAtividade!A:A,RamoAtividade!B:B) -> MODA FESTA | E2533: 0 | F2533: =LOOKUP(E2533,Finalidades!A:A,Finalidades!B:B) -> #N/A | G2533: N | H2533: N | I2533: N | J2533: N
A2534: 25520 | B2534: SORAYA ANDRADE PAULINO | C2534: 12 | D2534: =LOOKUP(C2534,RamoAtividade!A:A,RamoAtividade!B:B) -> MODA FESTA | E2534: 0 | F2534: =LOOKUP(E2534,Finalidades!A:A,Finalidades!B:B) -> #N/A | G2534: N | H2534: N | I2534: N | J2534: N
A2535: 25523 | B2535: CRISTIANE FELIPE RIBEIRO DE ARAUJO CORTES 01309848688 | C2535: 12 | D2535: =LOOKUP(C2535,RamoAtividade!A:A,RamoAtividade!B:B) -> MODA FESTA | E2535: 0 | F2535: =LOOKUP(E2535,Finalidades!A:A,Finalidades!B:B) -> #N/A | G2535: N | H2535: N | I2535: N | J2535: N
A2536: 25524 | B2536: R D LAY CS MODA FEMININA LTDA EPP | C2536: 12 | D2536: =LOOKUP(C2536,RamoAtividade!A:A,RamoAtividade!B:B) -> MODA FESTA | E2536: 0 | F2536: =LOOKUP(E2536,Finalidades!A:A,Finalidades!B:B) -> #N/A | G2536: N | H2536: N | I2536: N | J2536: N
A2537: 25528 | B2537: M C GONZALEZ SIMABULULO EPP | C2537: 12 | D2537: =LOOKUP(C2537,RamoAtividade!A:A,RamoAtividade!B:B) -> MODA FESTA | E2537: 0 | F2537: =LOOKUP(E2537,Finalidades!A:A,Finalidades!B:B) -> #N/A | G2537: N | H2537: N | I2537: N | J2537: N
A2538: 25529 | B2538: AR13 ARTIGOS DOS VESTUARIOS LTDA | C2538: 0 | D2538: =LOOKUP(C2538,RamoAtividade!A:A,RamoAtividade!B:B) -> #N/A | E2538: 0 | F2538: =LOOKUP(E2538,Finalidades!A:A,Finalidades!B:B) -> #N/A
A2539: 25538 | B2539: IND E COM DE CONF GUEDA LTDA | C2539: 20 | D2539: =LOOKUP(C2539,RamoAtividade!A:A,RamoAtividade!B:B) -> OUTROS SEGMENTOS | E2539: 0 | F2539: =LOOKUP(E2539,Finalidades!A:A,Finalidades!B:B) -> #N/A | G2539: N | H2539: N | I2539: N | J2539: N
A2540: 25545 | B2540: MAGALI LOUBAQUE CPF 035.215.126 - 90 ME | C2540: 6 | D2540: =LOOKUP(C2540,RamoAtividade!A:A,RamoAtividade!B:B) -> COM VAREJISTA DE TECIDOS | E2540: 0 | F2540: =LOOKUP(E2540,Finalidades!A:A,Finalidades!B:B) -> #N/A | G2540: N | H2540: N | I2540: N | J2540: N
A2541: 25546 | B2541: DANUBIO MALHAS LTDA ME | C2541: 12 | D2541: =LOOKUP(C2541,RamoAtividade!A:A,RamoAtividade!B:B) -> MODA FESTA | E2541: 0 | F2541: =LOOKUP(E2541,Finalidades!A:A,Finalidades!B:B) -> #N/A | G2541: N | H2541: N | I2541: N | J2541: N
A2542: 25547 | B2542: MARISOL VESTUµRIO SA | C2542: 12 | D2542: =LOOKUP(C2542,RamoAtividade!A:A,RamoAtividade!B:B) -> MODA FESTA | E2542: 0 | F2542: =LOOKUP(E2542,Finalidades!A:A,Finalidades!B:B) -> #N/A | G2542: N | H2542: N | I2542: N | J2542: N
A2543: 25549 | B2543: ONEIDA DE JESUS VAZ DE MELO-ME | C2543: 12 | D2543: =LOOKUP(C2543,RamoAtividade!A:A,RamoAtividade!B:B) -> MODA FESTA | E2543: 0 | F2543: =LOOKUP(E2543,Finalidades!A:A,Finalidades!B:B) -> #N/A | G2543: N | H2543: N | I2543: N | J2543: N
A2544: 25550 | B2544: R F COM DE TEC E RETALHOS LTDA EPP | C2544: 0 | D2544: =LOOKUP(C2544,RamoAtividade!A:A,RamoAtividade!B:B) -> #N/A | E2544: 0 | F2544: =LOOKUP(E2544,Finalidades!A:A,Finalidades!B:B) -> #N/A | G2544: N | H2544: N | I2544: N | J2544: N
A2545: 25551 | B2545: PETY MARILIA IND DE CONF LTDA - ME | C2545: 0 | D2545: =LOOKUP(C2545,RamoAtividade!A:A,RamoAtividade!B:B) -> #N/A | E2545: 0 | F2545: =LOOKUP(E2545,Finalidades!A:A,Finalidades!B:B) -> #N/A | G2545: N | H2545: N | I2545: N | J2545: N
A2546: 25564 | B2546: RENATO CALDEIRA FRANCO 71233725653 | C2546: 0 | D2546: =LOOKUP(C2546,RamoAtividade!A:A,RamoAtividade!B:B) -> #N/A | E2546: 0 | F2546: =LOOKUP(E2546,Finalidades!A:A,Finalidades!B:B) -> #N/A | G2546: N | H2546: N | I2546: N | J2546: N
A2547: 25566 | B2547: J T H MODAS LTDA | C2547: 12 | D2547: =LOOKUP(C2547,RamoAtividade!A:A,RamoAtividade!B:B) -> MODA FESTA | E2547: 0 | F2547: =LOOKUP(E2547,Finalidades!A:A,Finalidades!B:B) -> #N/A | G2547: N | H2547: N | I2547: N | J2547: N
A2548: 25573 | B2548: ELVIRA BEGNAMI CORREA 85592587600 | C2548: 0 | D2548: =LOOKUP(C2548,RamoAtividade!A:A,RamoAtividade!B:B) -> #N/A | E2548: 0 | F2548: =LOOKUP(E2548,Finalidades!A:A,Finalidades!B:B) -> #N/A
A2549: 25574 | B2549: EURIPEDES DONIZETE DA LUZ RESENDE ME | C2549: 0 | D2549: =LOOKUP(C2549,RamoAtividade!A:A,RamoAtividade!B:B) -> #N/A | E2549: 0 | F2549: =LOOKUP(E2549,Finalidades!A:A,Finalidades!B:B) -> #N/A | G2549: N | H2549: N | I2549: N | J2549: N
A2550: 25580 | B2550: M A F GOMES EPP | C2550: 12 | D2550: =LOOKUP(C2550,RamoAtividade!A:A,RamoAtividade!B:B) -> MODA FESTA | E2550: 0 | F2550: =LOOKUP(E2550,Finalidades!A:A,Finalidades!B:B) -> #N/A | G2550: N | H2550: N | I2550: N | J2550: N
A2551: 25581 | B2551: CASSIA TULIA OLIVEIRA URSINE SILVA - 388.486.196-49 - ME | C2551: 12 | D2551: =LOOKUP(C2551,RamoAtividade!A:A,RamoAtividade!B:B) -> MODA FESTA | E2551: 0 | F2551: =LOOKUP(E2551,Finalidades!A:A,Finalidades!B:B) -> #N/A | G2551: N | H2551: N | I2551: N | J2551: N
A2552: 25584 | B2552: ISAIAS LAGE DA LUZ 06464382632 | C2552: 12 | D2552: =LOOKUP(C2552,RamoAtividade!A:A,RamoAtividade!B:B) -> MODA FESTA | E2552: 0 | F2552: =LOOKUP(E2552,Finalidades!A:A,Finalidades!B:B) -> #N/A | G2552: N | H2552: N | I2552: N | J2552: N
A2553: 25592 | B2553: B & D CONF LT - ME | C2553: 12 | D2553: =LOOKUP(C2553,RamoAtividade!A:A,RamoAtividade!B:B) -> MODA FESTA | E2553: 0 | F2553: =LOOKUP(E2553,Finalidades!A:A,Finalidades!B:B) -> #N/A | G2553: N | H2553: N | I2553: N | J2553: N
A2554: 25594 | B2554: CRM INDUSTRIA TEXTIL LTDA | C2554: 0 | D2554: =LOOKUP(C2554,RamoAtividade!A:A,RamoAtividade!B:B) -> #N/A | E2554: 0 | F2554: =LOOKUP(E2554,Finalidades!A:A,Finalidades!B:B) -> #N/A | G2554: N | H2554: N | I2554: N | J2554: N
A2555: 25600 | B2555: POLLYMAR MODAS LTDA ME | C2555: 12 | D2555: =LOOKUP(C2555,RamoAtividade!A:A,RamoAtividade!B:B) -> MODA FESTA | E2555: 0 | F2555: =LOOKUP(E2555,Finalidades!A:A,Finalidades!B:B) -> #N/A | G2555: N | H2555: N | I2555: N | J2555: N
...

Sheet Finalidades
A1: Cod | B1: Descricao
A2: 1 | B2: Envio para Deposito
A3: 2 | B3: Consumo Proprio
A4: 3 | B4: Envio para Industrializa‡Æo
A5: 4 | B5: Revenda de Mercadoria

Sheet RamoAtividade
A1: Cod | B1: Descricao
A2: 1 | B2: ALFAIATARIA
A3: 2 | B3: AVIAMENTO E ARMARINHO
A4: 3 | B4: CAMA, MESA,BANHO E ENXOVAL
A5: 4 | B5: CAMISARIA
A6: 5 | B6: COM ATACADISTA DE TECIDOS
A7: 6 | B7: COM VAREJISTA DE TECIDOS
A8: 7 | B8: DECORA€ÇO, FESTAS E EVENTOS
A9: 8 | B9: FACCIONISTA
A10: 9 | B10: FEIRANTE
A11: 10 | B11: LINGERIE
A12: 11 | B12: MODA FEMININA ADULTO
A13: 12 | B13: MODA FESTA
... A21: 20 | B21: OUTROS SEGMENTOS
